Workbook
Name Slicer_DAY: #N/A
Name Slicer_NONTH: #N/A
Name Slicer_YEAR: #N/A
Name TOTALUSD: 'DATA '!$N$72

Sheet Dashboard 

Sheet STATISTICAL SUMMARY
A2: Retail Price (USD) | C2: Order Quantity | E2: Tax (USD) | G2: Total (USD)
A4: Mean | B4: 84.418571 | C4: Mean | D4: 2.4 | E4: Mean | F4: 14.0976 | G4: Mean | H4: 155.0736
A5: Standard Error | B5: 6.8180606 | C5: Standard Error | D5: 0.1594504 | E5: Standard Error | F5: 0.46547283 | G5: Standard Error | H5: 5.1202011
A6: Median | B6: 69.99 | C6: Median | D6: 2 | E6: Median | F6: 14.995 | G6: Median | H6: 164.945
A7: Mode | B7: 49.99 | C7: Mode | D7: 1 | E7: Mode | F7: 7.996 | G7: Mode | H7: 87.956
A8: Standard Deviation | B8: 57.043988 | C8: Standard Deviation | D8: 1.3340578 | E8: Standard Deviation | F8: 3.8944251 | G8: Standard Deviation | H8: 42.838676
A9: Sample Variance | B9: 3254.0166 | C9: Sample Variance | D9: 1.7797101 | E9: Sample Variance | F9: 15.166547 | G9: Sample Variance | H9: 1835.1522
A10: Kurtosis | B10: -0.63579951 | C10: Kurtosis | D10: -0.80466761 | E10: Kurtosis | F10: 3.7297079 | G10: Kurtosis | H10: 3.7297079
A11: Skewness | B11: 0.75035601 | C11: Skewness | D11: 0.5791067 | E11: Skewness | F11: 0.52255425 | G11: Skewness | H11: 0.52255425
A12: Range | B12: 180 | C12: Range | D12: 4 | E12: Range | F12: 26.998 | G12: Range | H12: 296.978
A13: Minimum | B13: 19.99 | C13: Minimum | D13: 1 | E13: Minimum | F13: 2.999 | G13: Minimum | H13: 32.989
A14: Maximum | B14: 199.99 | C14: Maximum | D14: 5 | E14: Maximum | F14: 29.997 | G14: Maximum | H14: 329.967
A15: Sum | B15: 5909.3 | C15: Sum | D15: 168 | E15: Sum | F15: 986.832 | G15: Sum | H15: 10855.152
A16: Count | B16: 70 | C16: Count | D16: 70 | E16: Count | F16: 70 | G16: Count | H16: 70
B17: 1 | D17: 3 | F17: 5 | H17: 7
B19: Retail_Price(USD) | C19: Order_Quantity | D19: Tax_(USD) | E19: Total_(USD)
A20: Retail_Price(USD) | B20: 1
A21: Order_Quantity | B21: -0.82157371 | C21: 1
A22: Tax_(USD) | B22: 0.58996369 | C22: -0.26758069 | D22: 1
A23: Total_(USD) | B23: 0.58996369 | C23: -0.26758069 | D23: 1 | E23: 1
A26: SUMMARY OUTPUT
A28: Regression Statistics
A29: Multiple R | B29: 1
A30: R Square | B30: 1
A31: Adjusted R Square | B31: 1
A32: Standard Error | B32: 2.8249834e-14
A33: Observations | B33: 70
A35: ANOVA
B36: df | C36: SS | D36: MS | E36: F | F36: Significance F
A37: Regression | B37: 3 | C37: 126625.5 | D37: 42208.499 | E37: 5.2889337e+31 | F37: 0
A38: Residual | B38: 66 | C38: 5.2671505e-26 | D38: 7.9805311e-28
A39: Total | B39: 69 | C39: 126625.5
B41: Coefficients | C41: Standard Error | D41: t Stat | E41: P-value | F41: Lower 95% | G41: Upper 95% | H41: Lower 95.0% | I41: Upper 95.0%
A42: Intercept | B42: -2.2737368e-13 | C42: 1.9298673e-14 | D42: -11.781829 | E42: 6.954356e-18 | F42: -2.6590472e-13 | G42: -1.8884263e-13 | H42: -2.6590472e-13 | I42: -1.8884263e-13
A43: Retail_Price(USD) | B43: 1.0196819e-15 | C43: 1.4152519e-16 | D43: 7.2049496 | E43: 6.9905125e-10 | F43: 7.371177e-16 | G43: 1.302246e-15 | H43: 7.371177e-16 | I43: 1.302246e-15
A44: Order_Quantity | B44: 1.178321e-14 | C44: 5.0711452e-15 | D44: 2.3235797 | E44: 0.023237861 | F44: 1.6583421e-15 | G44: 2.1908078e-14 | H44: 1.6583421e-15 | I44: 2.1908078e-14
A45: Tax_(USD) | B45: 11 | C45: 1.2265503e-15 | D45: 8.9682419e+15 | E45: 0 | F45: 11 | G45: 11 | H45: 11 | I45: 11

Sheet DATA 
A1: Order No | B1: Order Date | C1: Customer Name | D1: Ship Date | E1: Shipping Delay | F1: YEAR | G1: MONTH | H1: DAY | I1: Retail_Price(USD) | J1: Order_Quantity | K1: Unit Price | L1: Net Revenue | M1: Tax_(USD) | N1: Total_(USD) | O1: Tax Rate(%) | P1: Net Revenue2 | Q1: Gross tax | R1: Repeat Order Rate | S1: Average Selling Price (ASP) | T1: Tax Rate | U1: Units per Transaction
A2: 1001 | B2: 45292 | C2: John Smith | D2: 45294 | E2: ='DATA '!$D2-'DATA '!$B2 -> 2 | F2: =TEXT('DATA '!$D2,"YYYY") -> 2024 | G2: =TEXT('DATA '!$D2,"MMMM") -> January | H2: =TEXT('DATA '!$B2,"DDDD") -> Monday | I2: 49.99 | J2: 2 | K2: ='DATA '!$N2/'DATA '!$J2 -> 54.989 | L2: ='DATA '!$I2*'DATA '!$J2 -> 99.98 | M2: 9.998 | N2: 109.978 | O2: ='DATA '!$M2/'DATA '!$N2 -> 0.090909091 | P2: ='DATA '!$I2*'DATA '!$J2 -> 99.98 | Q2: ='DATA '!$P2+'DATA '!$M2 -> 109.978 | R2: =(COUNTIF(C:C, C2) - 1) / COUNTIF(C:C, C2) -> 0 | S2: =I72/J72 -> 35.174405 | T2: =M72/TOTALUSD -> 0.090909091 | U2: =J72/A72 -> 2.4
A3: 1002 | B3: 45292 | C3: Jane Doe | D3: 45295 | E3: ='DATA '!$D3-'DATA '!$B3 -> 3 | F3: =TEXT('DATA '!$D3,"YYYY") -> 2024 | G3: =TEXT('DATA '!$D3,"MMMM") -> January | H3: =TEXT('DATA '!$B3,"DDDD") -> Monday | I3: 29.99 | J3: 1 | K3: ='DATA '!$N3/'DATA '!$J3 -> 32.989 | L3: ='DATA '!$I3*'DATA '!$J3 -> 29.99 | M3: 2.999 | N3: 32.989 | O3: ='DATA '!$M3/'DATA '!$N3 -> 0.090909091 | P3: ='DATA '!$I3*'DATA '!$J3 -> 29.99 | Q3: ='DATA '!$P3+'DATA '!$M3 -> 32.989 | R3: =(COUNTIF(C:C, C3) - 1) / COUNTIF(C:C, C3) -> 0
A4: 1003 | B4: 45293 | C4: Michael Johnson | D4: 45298 | E4: ='DATA '!$D4-'DATA '!$B4 -> 5 | F4: =TEXT('DATA '!$D4,"YYYY") -> 2024 | G4: =TEXT('DATA '!$D4,"MMMM") -> January | H4: =TEXT('DATA '!$B4,"DDDD") -> Tuesday | I4: 99.99 | J4: 3 | K4: ='DATA '!$N4/'DATA '!$J4 -> 109.989 | L4: ='DATA '!$I4*'DATA '!$J4 -> 299.97 | M4: 29.997 | N4: 329.967 | O4: ='DATA '!$M4/'DATA '!$N4 -> 0.090909091 | P4: ='DATA '!$I4*'DATA '!$J4 -> 299.97 | Q4: ='DATA '!$P4+'DATA '!$M4 -> 329.967 | R4: =(COUNTIF(C:C, C4) - 1) / COUNTIF(C:C, C4) -> 0.5
A5: 1004 | B5: 45293 | C5: Emily Brown | D5: 45294 | E5: ='DATA '!$D5-'DATA '!$B5 -> 1 | F5: =TEXT('DATA '!$D5,"YYYY") -> 2024 | G5: =TEXT('DATA '!$D5,"MMMM") -> January | H5: =TEXT('DATA '!$B5,"DDDD") -> Tuesday | I5: 19.99 | J5: 4 | K5: ='DATA '!$N5/'DATA '!$J5 -> 21.989 | L5: ='DATA '!$I5*'DATA '!$J5 -> 79.96 | M5: 7.996 | N5: 87.956 | O5: ='DATA '!$M5/'DATA '!$N5 -> 0.090909091 | P5: ='DATA '!$I5*'DATA '!$J5 -> 79.96 | Q5: ='DATA '!$P5+'DATA '!$M5 -> 87.956 | R5: =(COUNTIF(C:C, C5) - 1) / COUNTIF(C:C, C5) -> 0.66666667
A6: 1005 | B6: 45294 | C6: David Wilson | D6: 45299 | E6: ='DATA '!$D6-'DATA '!$B6 -> 5 | F6: =TEXT('DATA '!$D6,"YYYY") -> 2024 | G6: =TEXT('DATA '!$D6,"MMMM") -> January | H6: =TEXT('DATA '!$B6,"DDDD") -> Wednesday | I6: 149.99 | J6: 1 | K6: ='DATA '!$N6/'DATA '!$J6 -> 164.989 | L6: ='DATA '!$I6*'DATA '!$J6 -> 149.99 | M6: 14.999 | N6: 164.989 | O6: ='DATA '!$M6/'DATA '!$N6 -> 0.090909091 | P6: ='DATA '!$I6*'DATA '!$J6 -> 149.99 | Q6: ='DATA '!$P6+'DATA '!$M6 -> 164.989 | R6: =(COUNTIF(C:C, C6) - 1) / COUNTIF(C:C, C6) -> 0.66666667
A7: 1006 | B7: 45294 | C7: Lisa Taylor | D7: 45297 | E7: ='DATA '!$D7-'DATA '!$B7 -> 3 | F7: =TEXT('DATA '!$D7,"YYYY") -> 2024 | G7: =TEXT('DATA '!$D7,"MMMM") -> January | H7: =TEXT('DATA '!$B7,"DDDD") -> Wednesday | I7: 79.99 | J7: 2 | K7: ='DATA '!$N7/'DATA '!$J7 -> 87.989 | L7: ='DATA '!$I7*'DATA '!$J7 -> 159.98 | M7: 15.998 | N7: 175.978 | O7: ='DATA '!$M7/'DATA '!$N7 -> 0.090909091 | P7: ='DATA '!$I7*'DATA '!$J7 -> 159.98 | Q7: ='DATA '!$P7+'DATA '!$M7 -> 175.978 | R7: =(COUNTIF(C:C, C7) - 1) / COUNTIF(C:C, C7) -> 0
A8: 1007 | B8: 45295 | C8: Daniel Martinez | D8: 45297 | E8: ='DATA '!$D8-'DATA '!$B8 -> 2 | F8: =TEXT('DATA '!$D8,"YYYY") -> 2024 | G8: =TEXT('DATA '!$D8,"MMMM") -> January | H8: =TEXT('DATA '!$B8,"DDDD") -> Thursday | I8: 39.99 | J8: 3 | K8: ='DATA '!$N8/'DATA '!$J8 -> 43.989 | L8: ='DATA '!$I8*'DATA '!$J8 -> 119.97 | M8: 11.997 | N8: 131.967 | O8: ='DATA '!$M8/'DATA '!$N8 -> 0.090909091 | P8: ='DATA '!$I8*'DATA '!$J8 -> 119.97 | Q8: ='DATA '!$P8+'DATA '!$M8 -> 131.967 | R8: =(COUNTIF(C:C, C8) - 1) / COUNTIF(C:C, C8) -> 0
A9: 1008 | B9: 45295 | C9: Sarah Anderson | D9: 45300 | E9: ='DATA '!$D9-'DATA '!$B9 -> 5 | F9: =TEXT('DATA '!$D9,"YYYY") -> 2024 | G9: =TEXT('DATA '!$D9,"MMMM") -> January | H9: =TEXT('DATA '!$B9,"DDDD") -> Thursday | I9: 69.99 | J9: 2 | K9: ='DATA '!$N9/'DATA '!$J9 -> 76.989 | L9: ='DATA '!$I9*'DATA '!$J9 -> 139.98 | M9: 13.998 | N9: 153.978 | O9: ='DATA '!$M9/'DATA '!$N9 -> 0.090909091 | P9: ='DATA '!$I9*'DATA '!$J9 -> 139.98 | Q9: ='DATA '!$P9+'DATA '!$M9 -> 153.978 | R9: =(COUNTIF(C:C, C9) - 1) / COUNTIF(C:C, C9) -> 0
A10: 1009 | B10: 45296 | C10: Christopher Thomas | D10: 45297 | E10: ='DATA '!$D10-'DATA '!$B10 -> 1 | F10: =TEXT('DATA '!$D10,"YYYY") -> 2024 | G10: =TEXT('DATA '!$D10,"MMMM") -> January | H10: =TEXT('DATA '!$B10,"DDDD") -> Friday | I10: 89.99 | J10: 1 | K10: ='DATA '!$N10/'DATA '!$J10 -> 98.989 | L10: ='DATA '!$I10*'DATA '!$J10 -> 89.99 | M10: 8.999 | N10: 98.989 | O10: ='DATA '!$M10/'DATA '!$N10 -> 0.090909091 | P10: ='DATA '!$I10*'DATA '!$J10 -> 89.99 | Q10: ='DATA '!$P10+'DATA '!$M10 -> 98.989 | R10: =(COUNTIF(C:C, C10) - 1) / COUNTIF(C:C, C10) -> 0
A11: 1010 | B11: 45296 | C11: Kimberly Garcia | D11: 45299 | E11: ='DATA '!$D11-'DATA '!$B11 -> 3 | F11: =TEXT('DATA '!$D11,"YYYY") -> 2024 | G11: =TEXT('DATA '!$D11,"MMMM") -> January | H11: =TEXT('DATA '!$B11,"DDDD") -> Friday | I11: 199.99 | J11: 1 | K11: ='DATA '!$N11/'DATA '!$J11 -> 219.989 | L11: ='DATA '!$I11*'DATA '!$J11 -> 199.99 | M11: 19.999 | N11: 219.989 | O11: ='DATA '!$M11/'DATA '!$N11 -> 0.090909091 | P11: ='DATA '!$I11*'DATA '!$J11 -> 199.99 | Q11: ='DATA '!$P11+'DATA '!$M11 -> 219.989 | R11: =(COUNTIF(C:C, C11) - 1) / COUNTIF(C:C, C11) -> 0
A12: 1011 | B12: 45297 | C12: William Hernandez | D12: 45298 | E12: ='DATA '!$D12-'DATA '!$B12 -> 1 | F12: =TEXT('DATA '!$D12,"YYYY") -> 2024 | G12: =TEXT('DATA '!$D12,"MMMM") -> January | H12: =TEXT('DATA '!$B12,"DDDD") -> Saturday | I12: 29.99 | J12: 5 | K12: ='DATA '!$N12/'DATA '!$J12 -> 32.989 | L12: ='DATA '!$I12*'DATA '!$J12 -> 149.95 | M12: 14.995 | N12: 164.945 | O12: ='DATA '!$M12/'DATA '!$N12 -> 0.090909091 | P12: ='DATA '!$I12*'DATA '!$J12 -> 149.95 | Q12: ='DATA '!$P12+'DATA '!$M12 -> 164.945 | R12: =(COUNTIF(C:C, C12) - 1) / COUNTIF(C:C, C12) -> 0
A13: 1012 | B13: 45297 | C13: Melissa Lopez | D13: 45299 | E13: ='DATA '!$D13-'DATA '!$B13 -> 2 | F13: =TEXT('DATA '!$D13,"YYYY") -> 2024 | G13: =TEXT('DATA '!$D13,"MMMM") -> January | H13: =TEXT('DATA '!$B13,"DDDD") -> Saturday | I13: 79.99 | J13: 2 | K13: ='DATA '!$N13/'DATA '!$J13 -> 87.989 | L13: ='DATA '!$I13*'DATA '!$J13 -> 159.98 | M13: 15.998 | N13: 175.978 | O13: ='DATA '!$M13/'DATA '!$N13 -> 0.090909091 | P13: ='DATA '!$I13*'DATA '!$J13 -> 159.98 | Q13: ='DATA '!$P13+'DATA '!$M13 -> 175.978 | R13: =(COUNTIF(C:C, C13) - 1) / COUNTIF(C:C, C13) -> 0
A14: 1013 | B14: 45298 | C14: Richard Perez | D14: 45300 | E14: ='DATA '!$D14-'DATA '!$B14 -> 2 | F14: =TEXT('DATA '!$D14,"YYYY") -> 2024 | G14: =TEXT('DATA '!$D14,"MMMM") -> January | H14: =TEXT('DATA '!$B14,"DDDD") -> Sunday | I14: 49.99 | J14: 3 | K14: ='DATA '!$N14/'DATA '!$J14 -> 54.989 | L14: ='DATA '!$I14*'DATA '!$J14 -> 149.97 | M14: 14.997 | N14: 164.967 | O14: ='DATA '!$M14/'DATA '!$N14 -> 0.090909091 | P14: ='DATA '!$I14*'DATA '!$J14 -> 149.97 | Q14: ='DATA '!$P14+'DATA '!$M14 -> 164.967 | R14: =(COUNTIF(C:C, C14) - 1) / COUNTIF(C:C, C14) -> 0
... A71: 1070 | B71: 45326 | C71: Jennifer Hernandez | D71: 45329 | E71: ='DATA '!$D71-'DATA '!$B71 -> 3 | F71: =TEXT('DATA '!$D71,"YYYY") -> 2024 | G71: =TEXT('DATA '!$D71,"MMMM") -> February | H71: =TEXT('DATA '!$B71,"DDDD") -> Sunday | I71: 149.99 | J71: 1 | K71: ='DATA '!$N71/'DATA '!$J71 -> 164.989 | L71: ='DATA '!$I71*'DATA '!$J71 -> 149.99 | M71: 14.999 | N71: 164.989 | O71: ='DATA '!$M71/'DATA '!$N71 -> 0.090909091 | P71: ='DATA '!$I71*'DATA '!$J71 -> 149.99 | Q71: ='DATA '!$P71+'DATA '!$M71 -> 164.989 | R71: =(COUNTIF(C:C, C71) - 1) / COUNTIF(C:C, C71) -> 0.5
A72: =COUNT(Table1[Order No]) -> 70 | E72: =AVERAGE(Table1[Shipping Delay]) -> 2.9 | I72: =SUM(Table1[Retail_Price(USD)]) -> 5909.3 | J72: =SUM(Table1[Order_Quantity]) -> 168 | M72: =SUM(Table1[Tax_(USD)]) -> 986.832 | N72: =SUM(Table1[Total_(USD)]) -> 10855.152 | P72: =SUM(Table1[Net Revenue2]) -> 9868.32 | Q72: =SUM(Table1[Gross tax]) -> 10855.152

Sheet SOURCE
A1: Order No | B1: Order Date | C1: Customer Name | D1: Ship Date | E1: Retail Price (USD) | F1: Order Quantity | G1: Tax (USD) | H1: Total (USD) | K1: Order Date | L1: Total (USD) | M1: Retail Price (USD) | N1: Order Quantity | O1: Tax (USD)
A2: 1001 | B2: 45292 | C2: John Smith | D2: 45294 | E2: 49.99 | F2: 2 | G2: 9.998 | H2: 109.978 | K2: 45292 | L2: 109.978 | M2: 49.99 | N2: 2 | O2: 9.998
A3: 1002 | B3: 45292 | C3: Jane Doe | D3: 45295 | E3: 29.99 | F3: 1 | G3: 2.999 | H3: 32.989 | K3: 45292 | L3: 32.989 | M3: 29.99 | N3: 1 | O3: 2.999
A4: 1003 | B4: 45293 | C4: Michael Johnson | D4: 45298 | E4: 99.99 | F4: 3 | G4: 29.997 | H4: 329.967 | K4: 45293 | L4: 329.967 | M4: 99.99 | N4: 3 | O4: 29.997
A5: 1004 | B5: 45293 | C5: Emily Brown | D5: 45294 | E5: 19.99 | F5: 4 | G5: 7.996 | H5: 87.956 | K5: 45293 | L5: 87.956 | M5: 19.99 | N5: 4 | O5: 7.996
A6: 1005 | B6: 45294 | C6: David Wilson | D6: 45299 | E6: 149.99 | F6: 1 | G6: 14.999 | H6: 164.989 | K6: 45294 | L6: 164.989 | M6: 149.99 | N6: 1 | O6: 14.999
A7: 1006 | B7: 45294 | C7: Lisa Taylor | D7: 45297 | E7: 79.99 | F7: 2 | G7: 15.998 | H7: 175.978 | K7: 45294 | L7: 175.978 | M7: 79.99 | N7: 2 | O7: 15.998
A8: 1007 | B8: 45295 | C8: Daniel Martinez | D8: 45297 | E8: 39.99 | F8: 3 | G8: 11.997 | H8: 131.967 | K8: 45295 | L8: 131.967 | M8: 39.99 | N8: 3 | O8: 11.997
A9: 1008 | B9: 45295 | C9: Sarah Anderson | D9: 45300 | E9: 69.99 | F9: 2 | G9: 13.998 | H9: 153.978 | K9: 45295 | L9: 153.978 | M9: 69.99 | N9: 2 | O9: 13.998
A10: 1009 | B10: 45296 | C10: Christopher Thomas | D10: 45297 | E10: 89.99 | F10: 1 | G10: 8.999 | H10: 98.989 | K10: 45296 | L10: 98.989 | M10: 89.99 | N10: 1 | O10: 8.999
A11: 1010 | B11: 45296 | C11: Kimberly Garcia | D11: 45299 | E11: 199.99 | F11: 1 | G11: 19.999 | H11: 219.989 | K11: 45296 | L11: 219.989 | M11: 199.99 | N11: 1 | O11: 19.999
A12: 1011 | B12: 45297 | C12: William Hernandez | D12: 45298 | E12: 29.99 | F12: 5 | G12: 14.995 | H12: 164.945 | K12: 45297 | L12: 164.945 | M12: 29.99 | N12: 5 | O12: 14.995
A13: 1012 | B13: 45297 | C13: Melissa Lopez | D13: 45299 | E13: 79.99 | F13: 2 | G13: 15.998 | H13: 175.978 | K13: 45297 | L13: 175.978 | M13: 79.99 | N13: 2 | O13: 15.998
... A71: 1070 | B71: 45326 | C71: Jennifer Hernandez | D71: 45329 | E71: 149.99 | F71: 1 | G71: 14.999 | H71: 164.989 | K71: 45326 | L71: 164.989 | M71: 149.99 | N71: 1 | O71: 14.999

Sheet PIVOT TABLES
A2: Sum of Total (USD) | I2: YEAR | J2: DAY | K2: Sum of Total (USD)
A3: 10855.152 | B3: =A3 -> 10855.152 | E3: Count of Order No | I3: 2024 | J3: Sunday | K3: 1671.725 | L3: =J3 -> Sunday | M3: =GETPIVOTDATA("Total (USD)",$I$2,"YEAR","2024","DAY","Sunday") -> 1671.725
E4: 70 | F4: =E4 -> 70 | J4: Monday | K4: 1396.747 | L4: =J4 -> Monday | M4: =GETPIVOTDATA("Total (USD)",$I$2,"YEAR","2024","DAY","Monday") -> 1396.747
A5: Sum of Order Quantity | J5: Tuesday | K5: 1594.725 | L5: =J5 -> Tuesday | M5: =GETPIVOTDATA("Total (USD)",$I$2,"YEAR","2024","DAY","Tuesday") -> 1594.725
A6: 168 | B6: =GETPIVOTDATA("Order Quantity",$A$5) -> 168 | J6: Wednesday | K6: 1638.736 | L6: =J6 -> Wednesday | M6: =GETPIVOTDATA("Total (USD)",$I$2,"YEAR","2024","DAY","Wednesday") -> 1638.736
J7: Thursday | K7: 1737.692 | L7: =J7 -> Thursday | M7: =GETPIVOTDATA("Total (USD)",$I$2,"YEAR","2024","DAY","Thursday") -> 1737.692
A8: Customer Name | B8: Sum of Total (USD) | C8: Customer | D8: Revenue | J8: Friday | K8: 1363.78 | L8: =J8 -> Friday | M8: =GETPIVOTDATA("Total (USD)",$I$2,"YEAR","2024","DAY","Friday") -> 1363.78
A9: Jennifer Davis | B9: 538.912 | C9: =A9 -> Jennifer Davis | D9: =B9 -> 538.912 | J9: Saturday | K9: 1451.747 | L9: =J9 -> Saturday | M9: =GETPIVOTDATA("Total (USD)",$I$2,"YEAR","2024","DAY","Saturday") -> 1451.747
A10: Michael Johnson | B10: 505.945 | C10: =A10 -> Michael Johnson | D10: =B10 -> 505.945 | I10: 2024 Total | K10: 10855.152
A11: David Wilson | B11: 472.967 | C11: =A11 -> David Wilson | D11: =B11 -> 472.967 | I11: Grand Total | K11: 10855.152
A12: Jessica Wilson | B12: 395.967 | C12: =A12 -> Jessica Wilson | D12: =B12 -> 395.967
A13: David Rodriguez | B13: 329.912 | C13: =A13 -> David Rodriguez | D13: =B13 -> 329.912
A14: Grand Total | B14: 2243.703 | C14: =A14 -> Grand Total | D14: =B14 -> 2243.703 | I14: YEAR | J14: NONTH | K14: Sum of Total (USD)
C15: =A15 -> 0 | D15: =B15 -> 0 | I15: 2024 | J15: January | K15: 9194.449
C16: =A16 -> 0 | D16: =B16 -> 0 | J16: February | K16: 1660.703
C17: =A17 -> 0 | D17: =B17 -> 0 | I17: 2024 Total | K17: 10855.152
C18: =A18 -> 0 | D18: =B18 -> 0 | I18: Grand Total | K18: 10855.152
C19: =A19 -> 0 | D19: =B19 -> 0
C20: =A20 -> 0 | D20: =B20 -> 0 | I20: NONTH | J20: Sum of Order Quantity
C21: =A21 -> 0 | D21: =B21 -> 0 | I21: January | J21: 141
C22: =A22 -> 0 | D22: =B22 -> 0 | I22: February | J22: 27
C23: =A23 -> 0 | D23: =B23 -> 0 | I23: Grand Total | J23: 168
C24: =A24 -> 0 | D24: =B24 -> 0
C25: =A25 -> 0 | D25: =B25 -> 0 | I25: Sum of Total (USD)
C26: =A26 -> 0 | D26: =B26 -> 0 | I26: 10855.152
C27: =A27 -> 0 | D27: =B27 -> 0
C28: =A28 -> 0 | D28: =B28 -> 0 | I28: Sum of Units per Transaction
C29: =A29 -> 0 | D29: =B29 -> 0 | I29: 2.4615385
C30: =A30 -> 0 | D30: =B30 -> 0
C31: =A31 -> 0 | D31: =B31 -> 0
C32: =A32 -> 0 | D32: =B32 -> 0
C33: =A33 -> 0 | D33: =B33 -> 0 | I33: Row Labels
C34: =A34 -> 0 | D34: =B34 -> 0 | I34: Sunday
C35: =A35 -> 0 | D35: =B35 -> 0 | I35: Monday
C36: =A36 -> 0 | D36: =B36 -> 0 | I36: Tuesday
C37: =A37 -> 0 | D37: =B37 -> 0 | I37: Wednesday
C38: =A38 -> 0 | D38: =B38 -> 0 | I38: Thursday
C39: =A39 -> 0 | D39: =B39 -> 0 | I39: Friday
C40: =A40 -> 0 | D40: =B40 -> 0 | I40: Saturday
C41: =A41 -> 0 | D41: =B41 -> 0 | I41: Grand Total
...

Sheet RFM ANALYSIS
A1: Customer Name | B1: Monetary | C1: Frequency | D1: Last Shipping Date | E1: Last Order Date | F1: Recency (Order date) | G1: Recency (Ship date) | H1: Recency Score(O_ Date) | I1: Recency Score(S_Date) | J1: Reference date
A2: Amanda Martinez | B2: 164.989 | C2: 1 | D2: 45303 | E2: 45299 | F2: =$J$2 - E2 -> 27 | G2: =$J$2 - D2 -> 23 | H2: {=_xlfn.IFS(F2<=6, 5,F2<=13, 4,F2<=20, 3,F2<=27, 2,F2<=34,1)} -> 2 | I2: {=_xlfn.IFS(G2<=6, 5,G2<=13, 4,G2<=20, 3,G2<=27, 2,G2<=34,1)} -> 2 | J2: =MAX(E2:E52) -> 45326
A3: Amy Hernandez | B3: 164.967 | C3: 1 | D3: 45306 | E3: 45302 | F3: =$J$2 - E3 -> 24 | G3: =$J$2 - D3 -> 20 | H3: {=_xlfn.IFS(F3<=6, 5,F3<=13, 4,F3<=20, 3,F3<=277, 2,F3<=34,1)} -> 2 | I3: {=_xlfn.IFS(G3<=6, 5,G3<=13, 4,G3<=20, 3,G3<=27, 2,G3<=34,1)} -> 3
A4: Christopher Rodriguez | B4: 142.989 | C4: 1 | D4: 45308 | E4: 45303 | F4: =$J$2 - E4 -> 23 | G4: =$J$2 - D4 -> 18 | H4: {=_xlfn.IFS(F4<=6, 5,F4<=13, 4,F4<=20, 3,F4<=277, 2,F4<=34,1)} -> 2 | I4: {=_xlfn.IFS(G4<=6, 5,G4<=13, 4,G4<=20, 3,G4<=27, 2,G4<=34,1)} -> 3
A5: Christopher Thomas | B5: 98.989 | C5: 1 | D5: 45297 | E5: 45296 | F5: =$J$2 - E5 -> 30 | G5: =$J$2 - D5 -> 29 | H5: {=_xlfn.IFS(F5<=6, 5,F5<=13, 4,F5<=20, 3,F5<=277, 2,F5<=34,1)} -> 2 | I5: {=_xlfn.IFS(G5<=6, 5,G5<=13, 4,G5<=20, 3,G5<=27, 2,G5<=34,1)} -> 1
A6: Daniel Brown | B6: 241.934 | C6: 2 | D6: 45330 | E6: 45326 | F6: =$J$2 - E6 -> 0 | G6: =$J$2 - D6 -> -4 | H6: {=_xlfn.IFS(F6<=6, 5,F6<=13, 4,F6<=20, 3,F6<=277, 2,F6<=34,1)} -> 5 | I6: {=_xlfn.IFS(G6<=6, 5,G6<=13, 4,G6<=20, 3,G6<=27, 2,G6<=34,1)} -> 5
A7: Daniel Davis | B7: 219.989 | C7: 1 | D7: 45311 | E7: 45310 | F7: =$J$2 - E7 -> 16 | G7: =$J$2 - D7 -> 15 | H7: {=_xlfn.IFS(F7<=6, 5,F7<=13, 4,F7<=20, 3,F7<=277, 2,F7<=34,1)} -> 3 | I7: {=_xlfn.IFS(G7<=6, 5,G7<=13, 4,G7<=20, 3,G7<=27, 2,G7<=34,1)} -> 3
A8: Daniel Hernandez | B8: 296.956 | C8: 2 | D8: 45324 | E8: 45322 | F8: =$J$2 - E8 -> 4 | G8: =$J$2 - D8 -> 2 | H8: {=_xlfn.IFS(F8<=6, 5,F8<=13, 4,F8<=20, 3,F8<=277, 2,F8<=34,1)} -> 5 | I8: {=_xlfn.IFS(G8<=6, 5,G8<=13, 4,G8<=20, 3,G8<=27, 2,G8<=34,1)} -> 5
A9: Daniel Martinez | B9: 131.967 | C9: 1 | D9: 45297 | E9: 45295 | F9: =$J$2 - E9 -> 31 | G9: =$J$2 - D9 -> 29 | H9: {=_xlfn.IFS(F9<=6, 5,F9<=13, 4,F9<=20, 3,F9<=277, 2,F9<=34,1)} -> 2 | I9: {=_xlfn.IFS(G9<=6, 5,G9<=13, 4,G9<=20, 3,G9<=27, 2,G9<=34,1)} -> 1
A10: Daniel Smith | B10: 219.989 | C10: 1 | D10: 45302 | E10: 45301 | F10: =$J$2 - E10 -> 25 | G10: =$J$2 - D10 -> 24 | H10: {=_xlfn.IFS(F10<=6, 5,F10<=13, 4,F10<=20, 3,F10<=277, 2,F10<=34,1)} -> 2 | I10: {=_xlfn.IFS(G10<=6, 5,G10<=13, 4,G10<=20, 3,G10<=27, 2,G10<=34,1)} -> 2
A11: Daniel Wilson | B11: 164.945 | C11: 1 | D11: 45310 | E11: 45306 | F11: =$J$2 - E11 -> 20 | G11: =$J$2 - D11 -> 16 | H11: {=_xlfn.IFS(F11<=6, 5,F11<=13, 4,F11<=20, 3,F11<=277, 2,F11<=34,1)} -> 3 | I11: {=_xlfn.IFS(G11<=6, 5,G11<=13, 4,G11<=20, 3,G11<=27, 2,G11<=34,1)} -> 3
A12: David Brown | B12: 87.956 | C12: 1 | D12: 45310 | E12: 45308 | F12: =$J$2 - E12 -> 18 | G12: =$J$2 - D12 -> 16 | H12: {=_xlfn.IFS(F12<=6, 5,F12<=13, 4,F12<=20, 3,F12<=277, 2,F12<=34,1)} -> 3 | I12: {=_xlfn.IFS(G12<=6, 5,G12<=13, 4,G12<=20, 3,G12<=27, 2,G12<=34,1)} -> 3
A13: David Martinez | B13: 175.978 | C13: 1 | D13: 45321 | E13: 45320 | F13: =$J$2 - E13 -> 6 | G13: =$J$2 - D13 -> 5 | H13: {=_xlfn.IFS(F13<=6, 5,F13<=13, 4,F13<=20, 3,F13<=277, 2,F13<=34,1)} -> 5 | I13: {=_xlfn.IFS(G13<=6, 5,G13<=13, 4,G13<=20, 3,G13<=27, 2,G13<=34,1)} -> 5
A14: David Rodriguez | B14: 329.912 | C14: 2 | D14: 45325 | E14: 45323 | F14: =$J$2 - E14 -> 3 | G14: =$J$2 - D14 -> 1 | H14: {=_xlfn.IFS(F14<=6, 5,F14<=13, 4,F14<=20, 3,F14<=277, 2,F14<=34,1)} -> 5 | I14: {=_xlfn.IFS(G14<=6, 5,G14<=13, 4,G14<=20, 3,G14<=27, 2,G14<=34,1)} -> 5
... A52: William Hernandez | B52: 164.945 | C52: 1 | D52: 45298 | E52: 45297 | F52: =$J$2 - E52 -> 29 | G52: =$J$2 - D52 -> 28 | H52: {=_xlfn.IFS(F52<=6, 5,F52<=13, 4,F52<=20, 3,F52<=277, 2,F52<=34,1)} -> 2 | I52: {=_xlfn.IFS(G52<=6, 5,G52<=13, 4,G52<=20, 3,G52<=27, 2,G52<=34,1)} -> 1
A53: Grand Total | B53: 10855.152 | C53: 70 | D53: 45330 | E53: 45326

Sheet FORECAST(Total USD)
A1: Order Date | B1: Total_(USD) | C1: Forecast(Total_(USD)) | D1: Lower Confidence Bound(Total_(USD)) | E1: Upper Confidence Bound(Total_(USD)) | G1: Statistic | H1: Value
A2: 45292 | B2: 71.4835 | G2: Alpha | H2: =_xlfn.FORECAST.ETS.STAT($B$2:$B$36,$A$2:$A$36,1,1,1) -> 0.25
A3: 45293 | B3: 208.9615 | G3: Beta | H3: =_xlfn.FORECAST.ETS.STAT($B$2:$B$36,$A$2:$A$36,2,1,1) -> 0.001
A4: 45294 | B4: 170.4835 | G4: Gamma | H4: =_xlfn.FORECAST.ETS.STAT($B$2:$B$36,$A$2:$A$36,3,1,1) -> 0.749
A5: 45295 | B5: 142.9725 | G5: MASE | H5: =_xlfn.FORECAST.ETS.STAT($B$2:$B$36,$A$2:$A$36,4,1,1) -> 0.90156941
A6: 45296 | B6: 159.489 | G6: SMAPE | H6: =_xlfn.FORECAST.ETS.STAT($B$2:$B$36,$A$2:$A$36,5,1,1) -> 0.1840135
A7: 45297 | B7: 170.4615 | G7: MAE | H7: =_xlfn.FORECAST.ETS.STAT($B$2:$B$36,$A$2:$A$36,6,1,1) -> 28.30325
A8: 45298 | B8: 153.978 | G8: RMSE | H8: =_xlfn.FORECAST.ETS.STAT($B$2:$B$36,$A$2:$A$36,7,1,1) -> 31.067317
A9: 45299 | B9: 126.4725
A10: 45300 | B10: 142.9725
A11: 45301 | B11: 192.467
A12: 45302 | B12: 170.4725
A13: 45303 | B13: 115.4725
A14: 45304 | B14: 159.4835
A15: 45305 | B15: 175.978
A16: 45306 | B16: 170.4615
A17: 45307 | B17: 153.978
A18: 45308 | B18: 126.4725
A19: 45309 | B19: 142.9725
A20: 45310 | B20: 192.467
... A35: 45325 | B35: 164.967
A36: 45326 | B36: 131.978 | C36: 131.978 | D36: 131.978 | E36: 131.978
A37: 45327 | C37: =_xlfn.FORECAST.ETS(A37,$B$2:$B$36,$A$2:$A$36,1,1) -> 179.85902 | D37: =C37-_xlfn.FORECAST.ETS.CONFINT(A37,$B$2:$B$36,$A$2:$A$36,0.95,1,1) -> 110.45047 | E37: =C37+_xlfn.FORECAST.ETS.CONFINT(A37,$B$2:$B$36,$A$2:$A$36,0.95,1,1) -> 249.26756
A38: 45328 | C38: =_xlfn.FORECAST.ETS(A38,$B$2:$B$36,$A$2:$A$36,1,1) -> 180.12886 | D38: =C38-_xlfn.FORECAST.ETS.CONFINT(A38,$B$2:$B$36,$A$2:$A$36,0.95,1,1) -> 108.56731 | E38: =C38+_xlfn.FORECAST.ETS.CONFINT(A38,$B$2:$B$36,$A$2:$A$36,0.95,1,1) -> 251.69042
A39: 45329 | C39: =_xlfn.FORECAST.ETS(A39,$B$2:$B$36,$A$2:$A$36,1,1) -> 156.65191 | D39: =C39-_xlfn.FORECAST.ETS.CONFINT(A39,$B$2:$B$36,$A$2:$A$36,0.95,1,1) -> 82.983808 | E39: =C39+_xlfn.FORECAST.ETS.CONFINT(A39,$B$2:$B$36,$A$2:$A$36,0.95,1,1) -> 230.32002
A40: 45330 | C40: =_xlfn.FORECAST.ETS(A40,$B$2:$B$36,$A$2:$A$36,1,1) -> 133.29903 | D40: =C40-_xlfn.FORECAST.ETS.CONFINT(A40,$B$2:$B$36,$A$2:$A$36,0.95,1,1) -> 57.566899 | E40: =C40+_xlfn.FORECAST.ETS.CONFINT(A40,$B$2:$B$36,$A$2:$A$36,0.95,1,1) -> 209.03116
A41: 45331 | C41: =_xlfn.FORECAST.ETS(A41,$B$2:$B$36,$A$2:$A$36,1,1) -> 181.1417 | D41: =C41-_xlfn.FORECAST.ETS.CONFINT(A41,$B$2:$B$36,$A$2:$A$36,0.95,1,1) -> 78.27358 | E41: =C41+_xlfn.FORECAST.ETS.CONFINT(A41,$B$2:$B$36,$A$2:$A$36,0.95,1,1) -> 284.00982
A42: 45332 | C42: =_xlfn.FORECAST.ETS(A42,$B$2:$B$36,$A$2:$A$36,1,1) -> 181.41155 | D42: =C42-_xlfn.FORECAST.ETS.CONFINT(A42,$B$2:$B$36,$A$2:$A$36,0.95,1,1) -> 77.031898 | E42: =C42+_xlfn.FORECAST.ETS.CONFINT(A42,$B$2:$B$36,$A$2:$A$36,0.95,1,1) -> 285.7912
A43: 45333 | C43: =_xlfn.FORECAST.ETS(A43,$B$2:$B$36,$A$2:$A$36,1,1) -> 157.9346 | D43: =C43-_xlfn.FORECAST.ETS.CONFINT(A43,$B$2:$B$36,$A$2:$A$36,0.95,1,1) -> 52.053372 | E43: =C43+_xlfn.FORECAST.ETS.CONFINT(A43,$B$2:$B$36,$A$2:$A$36,0.95,1,1) -> 263.81583
A44: 45334 | C44: =_xlfn.FORECAST.ETS(A44,$B$2:$B$36,$A$2:$A$36,1,1) -> 134.58172 | D44: =C44-_xlfn.FORECAST.ETS.CONFINT(A44,$B$2:$B$36,$A$2:$A$36,0.95,1,1) -> 27.208405 | E44: =C44+_xlfn.FORECAST.ETS.CONFINT(A44,$B$2:$B$36,$A$2:$A$36,0.95,1,1) -> 241.95503
A45: 45335 | C45: =_xlfn.FORECAST.ETS(A45,$B$2:$B$36,$A$2:$A$36,1,1) -> 182.42439 | D45: =C45-_xlfn.FORECAST.ETS.CONFINT(A45,$B$2:$B$36,$A$2:$A$36,0.95,1,1) -> 54.306256 | E45: =C45+_xlfn.FORECAST.ETS.CONFINT(A45,$B$2:$B$36,$A$2:$A$36,0.95,1,1) -> 310.54252
A46: 45336 | C46: =_xlfn.FORECAST.ETS(A46,$B$2:$B$36,$A$2:$A$36,1,1) -> 182.69423 | D46: =C46-_xlfn.FORECAST.ETS.CONFINT(A46,$B$2:$B$36,$A$2:$A$36,0.95,1,1) -> 53.321047 | E46: =C46+_xlfn.FORECAST.ETS.CONFINT(A46,$B$2:$B$36,$A$2:$A$36,0.95,1,1) -> 312.06742
A47: 45337 | C47: =_xlfn.FORECAST.ETS(A47,$B$2:$B$36,$A$2:$A$36,1,1) -> 159.21729 | D47: =C47-_xlfn.FORECAST.ETS.CONFINT(A47,$B$2:$B$36,$A$2:$A$36,0.95,1,1) -> 28.59153 | E47: =C47+_xlfn.FORECAST.ETS.CONFINT(A47,$B$2:$B$36,$A$2:$A$36,0.95,1,1) -> 289.84304
A48: 45338 | C48: =_xlfn.FORECAST.ETS(A48,$B$2:$B$36,$A$2:$A$36,1,1) -> 135.8644 | D48: =C48-_xlfn.FORECAST.ETS.CONFINT(A48,$B$2:$B$36,$A$2:$A$36,0.95,1,1) -> 3.9884627 | E48: =C48+_xlfn.FORECAST.ETS.CONFINT(A48,$B$2:$B$36,$A$2:$A$36,0.95,1,1) -> 267.74035
... A62: 45352 | C62: =_xlfn.FORECAST.ETS(A62,$B$2:$B$36,$A$2:$A$36,1,1) -> 187.82498 | D62: =C62-_xlfn.FORECAST.ETS.CONFINT(A62,$B$2:$B$36,$A$2:$A$36,0.95,1,1) -> -14.168945 | E62: =C62+_xlfn.FORECAST.ETS.CONFINT(A62,$B$2:$B$36,$A$2:$A$36,0.95,1,1) -> 389.81891

Sheet FORECAST(Retail_price)
A1: Order Date | B1: Retail_Price(USD) | C1: Forecast(Retail_Price(USD)) | D1: Lower Confidence Bound(Retail_Price(USD)) | E1: Upper Confidence Bound(Retail_Price(USD)) | G1: Statistic | H1: Value
A2: 45292 | B2: 39.99 | G2: Alpha | H2: =_xlfn.FORECAST.ETS.STAT($B$2:$B$36,$A$2:$A$36,1,1,1) -> 0.25
A3: 45293 | B3: 59.99 | G3: Beta | H3: =_xlfn.FORECAST.ETS.STAT($B$2:$B$36,$A$2:$A$36,2,1,1) -> 0.001
A4: 45294 | B4: 114.99 | G4: Gamma | H4: =_xlfn.FORECAST.ETS.STAT($B$2:$B$36,$A$2:$A$36,3,1,1) -> 2.220446e-16
A5: 45295 | B5: 54.99 | G5: MASE | H5: =_xlfn.FORECAST.ETS.STAT($B$2:$B$36,$A$2:$A$36,4,1,1) -> 0.50745182
A6: 45296 | B6: 144.99 | G6: SMAPE | H6: =_xlfn.FORECAST.ETS.STAT($B$2:$B$36,$A$2:$A$36,5,1,1) -> 0.24754983
A7: 45297 | B7: 54.99 | G7: MAE | H7: =_xlfn.FORECAST.ETS.STAT($B$2:$B$36,$A$2:$A$36,6,1,1) -> 20.086634
A8: 45298 | B8: 89.99 | G8: RMSE | H8: =_xlfn.FORECAST.ETS.STAT($B$2:$B$36,$A$2:$A$36,7,1,1) -> 23.919802
A9: 45299 | B9: 84.99
A10: 45300 | B10: 54.99
A11: 45301 | B11: 114.99
A12: 45302 | B12: 64.99
A13: 45303 | B13: 74.99
A14: 45304 | B14: 109.99
A15: 45305 | B15: 119.99
A16: 45306 | B16: 54.99
A17: 45307 | B17: 89.99
A18: 45308 | B18: 84.99
A19: 45309 | B19: 54.99
A20: 45310 | B20: 114.99
... A35: 45325 | B35: 49.99
A36: 45326 | B36: 99.99 | C36: 99.99 | D36: 99.99 | E36: 99.99
A37: 45327 | C37: =_xlfn.FORECAST.ETS(A37,$B$2:$B$36,$A$2:$A$36,1,1) -> 83.963685 | D37: =C37-_xlfn.FORECAST.ETS.CONFINT(A37,$B$2:$B$36,$A$2:$A$36,0.95,1,1) -> 24.732223 | E37: =C37+_xlfn.FORECAST.ETS.CONFINT(A37,$B$2:$B$36,$A$2:$A$36,0.95,1,1) -> 143.19515
A38: 45328 | C38: =_xlfn.FORECAST.ETS(A38,$B$2:$B$36,$A$2:$A$36,1,1) -> 84.239877 | D38: =C38-_xlfn.FORECAST.ETS.CONFINT(A38,$B$2:$B$36,$A$2:$A$36,0.95,1,1) -> 23.171091 | E38: =C38+_xlfn.FORECAST.ETS.CONFINT(A38,$B$2:$B$36,$A$2:$A$36,0.95,1,1) -> 145.30866
A39: 45329 | C39: =_xlfn.FORECAST.ETS(A39,$B$2:$B$36,$A$2:$A$36,1,1) -> 84.516068 | D39: =C39-_xlfn.FORECAST.ETS.CONFINT(A39,$B$2:$B$36,$A$2:$A$36,0.95,1,1) -> 21.649607 | E39: =C39+_xlfn.FORECAST.ETS.CONFINT(A39,$B$2:$B$36,$A$2:$A$36,0.95,1,1) -> 147.38253
A40: 45330 | C40: =_xlfn.FORECAST.ETS(A40,$B$2:$B$36,$A$2:$A$36,1,1) -> 84.79226 | D40: =C40-_xlfn.FORECAST.ETS.CONFINT(A40,$B$2:$B$36,$A$2:$A$36,0.95,1,1) -> 20.16441 | E40: =C40+_xlfn.FORECAST.ETS.CONFINT(A40,$B$2:$B$36,$A$2:$A$36,0.95,1,1) -> 149.42011
A41: 45331 | C41: =_xlfn.FORECAST.ETS(A41,$B$2:$B$36,$A$2:$A$36,1,1) -> 85.068451 | D41: =C41-_xlfn.FORECAST.ETS.CONFINT(A41,$B$2:$B$36,$A$2:$A$36,0.95,1,1) -> 18.712557 | E41: =C41+_xlfn.FORECAST.ETS.CONFINT(A41,$B$2:$B$36,$A$2:$A$36,0.95,1,1) -> 151.42435
A42: 45332 | C42: =_xlfn.FORECAST.ETS(A42,$B$2:$B$36,$A$2:$A$36,1,1) -> 85.344643 | D42: =C42-_xlfn.FORECAST.ETS.CONFINT(A42,$B$2:$B$36,$A$2:$A$36,0.95,1,1) -> 17.291456 | E42: =C42+_xlfn.FORECAST.ETS.CONFINT(A42,$B$2:$B$36,$A$2:$A$36,0.95,1,1) -> 153.39783
A43: 45333 | C43: =_xlfn.FORECAST.ETS(A43,$B$2:$B$36,$A$2:$A$36,1,1) -> 85.620834 | D43: =C43-_xlfn.FORECAST.ETS.CONFINT(A43,$B$2:$B$36,$A$2:$A$36,0.95,1,1) -> 15.898812 | E43: =C43+_xlfn.FORECAST.ETS.CONFINT(A43,$B$2:$B$36,$A$2:$A$36,0.95,1,1) -> 155.34286
A44: 45334 | C44: =_xlfn.FORECAST.ETS(A44,$B$2:$B$36,$A$2:$A$36,1,1) -> 85.897026 | D44: =C44-_xlfn.FORECAST.ETS.CONFINT(A44,$B$2:$B$36,$A$2:$A$36,0.95,1,1) -> 14.532577 | E44: =C44+_xlfn.FORECAST.ETS.CONFINT(A44,$B$2:$B$36,$A$2:$A$36,0.95,1,1) -> 157.26147
A45: 45335 | C45: =_xlfn.FORECAST.ETS(A45,$B$2:$B$36,$A$2:$A$36,1,1) -> 86.173218 | D45: =C45-_xlfn.FORECAST.ETS.CONFINT(A45,$B$2:$B$36,$A$2:$A$36,0.95,1,1) -> 13.190922 | E45: =C45+_xlfn.FORECAST.ETS.CONFINT(A45,$B$2:$B$36,$A$2:$A$36,0.95,1,1) -> 159.15551
A46: 45336 | C46: =_xlfn.FORECAST.ETS(A46,$B$2:$B$36,$A$2:$A$36,1,1) -> 86.449409 | D46: =C46-_xlfn.FORECAST.ETS.CONFINT(A46,$B$2:$B$36,$A$2:$A$36,0.95,1,1) -> 11.8722 | E46: =C46+_xlfn.FORECAST.ETS.CONFINT(A46,$B$2:$B$36,$A$2:$A$36,0.95,1,1) -> 161.02662
A47: 45337 | C47: =_xlfn.FORECAST.ETS(A47,$B$2:$B$36,$A$2:$A$36,1,1) -> 86.725601 | D47: =C47-_xlfn.FORECAST.ETS.CONFINT(A47,$B$2:$B$36,$A$2:$A$36,0.95,1,1) -> 10.574923 | E47: =C47+_xlfn.FORECAST.ETS.CONFINT(A47,$B$2:$B$36,$A$2:$A$36,0.95,1,1) -> 162.87628
A48: 45338 | C48: =_xlfn.FORECAST.ETS(A48,$B$2:$B$36,$A$2:$A$36,1,1) -> 87.001792 | D48: =C48-_xlfn.FORECAST.ETS.CONFINT(A48,$B$2:$B$36,$A$2:$A$36,0.95,1,1) -> 9.2977441 | E48: =C48+_xlfn.FORECAST.ETS.CONFINT(A48,$B$2:$B$36,$A$2:$A$36,0.95,1,1) -> 164.70584
... A62: 45352 | C62: =_xlfn.FORECAST.ETS(A62,$B$2:$B$36,$A$2:$A$36,1,1) -> 90.868473 | D62: =C62-_xlfn.FORECAST.ETS.CONFINT(A62,$B$2:$B$36,$A$2:$A$36,0.95,1,1) -> -7.0073729 | E62: =C62+_xlfn.FORECAST.ETS.CONFINT(A62,$B$2:$B$36,$A$2:$A$36,0.95,1,1) -> 188.74432

Sheet FORECAST(Oder_Quantity)
A1: Order Date | B1: Order_Quantity | C1: Forecast(Order_Quantity) | D1: Lower Confidence Bound(Order_Quantity) | E1: Upper Confidence Bound(Order_Quantity) | G1: Statistic | H1: Value
A2: 45292 | B2: 1.5 | G2: Alpha | H2: =_xlfn.FORECAST.ETS.STAT($B$2:$B$36,$A$2:$A$36,1,1,1) -> 0.126
A3: 45293 | B3: 3.5 | G3: Beta | H3: =_xlfn.FORECAST.ETS.STAT($B$2:$B$36,$A$2:$A$36,2,1,1) -> 0.001
A4: 45294 | B4: 1.5 | G4: Gamma | H4: =_xlfn.FORECAST.ETS.STAT($B$2:$B$36,$A$2:$A$36,3,1,1) -> 2.220446e-16
A5: 45295 | B5: 2.5 | G5: MASE | H5: =_xlfn.FORECAST.ETS.STAT($B$2:$B$36,$A$2:$A$36,4,1,1) -> 0.42011774
A6: 45296 | B6: 1 | G6: SMAPE | H6: =_xlfn.FORECAST.ETS.STAT($B$2:$B$36,$A$2:$A$36,5,1,1) -> 0.16621009
A7: 45297 | B7: 3.5 | G7: MAE | H7: =_xlfn.FORECAST.ETS.STAT($B$2:$B$36,$A$2:$A$36,6,1,1) -> 0.39386038
A8: 45298 | B8: 2 | G8: RMSE | H8: =_xlfn.FORECAST.ETS.STAT($B$2:$B$36,$A$2:$A$36,7,1,1) -> 0.50808414
A9: 45299 | B9: 2.5
A10: 45300 | B10: 2.5
A11: 45301 | B11: 3
A12: 45302 | B12: 2.5
A13: 45303 | B13: 2.5
A14: 45304 | B14: 1.5
A15: 45305 | B15: 2
A16: 45306 | B16: 3.5
A17: 45307 | B17: 2
A18: 45308 | B18: 2.5
A19: 45309 | B19: 2.5
A20: 45310 | B20: 3
... A35: 45325 | B35: 3
A36: 45326 | B36: 2 | C36: 2 | D36: 2 | E36: 2
A37: 45327 | C37: =_xlfn.FORECAST.ETS(A37,$B$2:$B$36,$A$2:$A$36,1,1) -> 2.4875009 | D37: =C37-_xlfn.FORECAST.ETS.CONFINT(A37,$B$2:$B$36,$A$2:$A$36,0.95,1,1) -> 1.0798827 | E37: =C37+_xlfn.FORECAST.ETS.CONFINT(A37,$B$2:$B$36,$A$2:$A$36,0.95,1,1) -> 3.8951191
A38: 45328 | C38: =_xlfn.FORECAST.ETS(A38,$B$2:$B$36,$A$2:$A$36,1,1) -> 2.497518 | D38: =C38-_xlfn.FORECAST.ETS.CONFINT(A38,$B$2:$B$36,$A$2:$A$36,0.95,1,1) -> 1.0785935 | E38: =C38+_xlfn.FORECAST.ETS.CONFINT(A38,$B$2:$B$36,$A$2:$A$36,0.95,1,1) -> 3.9164425
A39: 45329 | C39: =_xlfn.FORECAST.ETS(A39,$B$2:$B$36,$A$2:$A$36,1,1) -> 2.5075351 | D39: =C39-_xlfn.FORECAST.ETS.CONFINT(A39,$B$2:$B$36,$A$2:$A$36,0.95,1,1) -> 1.077217 | E39: =C39+_xlfn.FORECAST.ETS.CONFINT(A39,$B$2:$B$36,$A$2:$A$36,0.95,1,1) -> 3.9378532
A40: 45330 | C40: =_xlfn.FORECAST.ETS(A40,$B$2:$B$36,$A$2:$A$36,1,1) -> 2.5175522 | D40: =C40-_xlfn.FORECAST.ETS.CONFINT(A40,$B$2:$B$36,$A$2:$A$36,0.95,1,1) -> 1.075754 | E40: =C40+_xlfn.FORECAST.ETS.CONFINT(A40,$B$2:$B$36,$A$2:$A$36,0.95,1,1) -> 3.9593504
A41: 45331 | C41: =_xlfn.FORECAST.ETS(A41,$B$2:$B$36,$A$2:$A$36,1,1) -> 2.5275693 | D41: =C41-_xlfn.FORECAST.ETS.CONFINT(A41,$B$2:$B$36,$A$2:$A$36,0.95,1,1) -> 1.0742051 | E41: =C41+_xlfn.FORECAST.ETS.CONFINT(A41,$B$2:$B$36,$A$2:$A$36,0.95,1,1) -> 3.9809335
A42: 45332 | C42: =_xlfn.FORECAST.ETS(A42,$B$2:$B$36,$A$2:$A$36,1,1) -> 2.5375864 | D42: =C42-_xlfn.FORECAST.ETS.CONFINT(A42,$B$2:$B$36,$A$2:$A$36,0.95,1,1) -> 1.072571 | E42: =C42+_xlfn.FORECAST.ETS.CONFINT(A42,$B$2:$B$36,$A$2:$A$36,0.95,1,1) -> 4.0026018
A43: 45333 | C43: =_xlfn.FORECAST.ETS(A43,$B$2:$B$36,$A$2:$A$36,1,1) -> 2.5476035 | D43: =C43-_xlfn.FORECAST.ETS.CONFINT(A43,$B$2:$B$36,$A$2:$A$36,0.95,1,1) -> 1.0708524 | E43: =C43+_xlfn.FORECAST.ETS.CONFINT(A43,$B$2:$B$36,$A$2:$A$36,0.95,1,1) -> 4.0243546
A44: 45334 | C44: =_xlfn.FORECAST.ETS(A44,$B$2:$B$36,$A$2:$A$36,1,1) -> 2.5576206 | D44: =C44-_xlfn.FORECAST.ETS.CONFINT(A44,$B$2:$B$36,$A$2:$A$36,0.95,1,1) -> 1.0690499 | E44: =C44+_xlfn.FORECAST.ETS.CONFINT(A44,$B$2:$B$36,$A$2:$A$36,0.95,1,1) -> 4.0461913
A45: 45335 | C45: =_xlfn.FORECAST.ETS(A45,$B$2:$B$36,$A$2:$A$36,1,1) -> 2.5676377 | D45: =C45-_xlfn.FORECAST.ETS.CONFINT(A45,$B$2:$B$36,$A$2:$A$36,0.95,1,1) -> 1.0671643 | E45: =C45+_xlfn.FORECAST.ETS.CONFINT(A45,$B$2:$B$36,$A$2:$A$36,0.95,1,1) -> 4.0681111
A46: 45336 | C46: =_xlfn.FORECAST.ETS(A46,$B$2:$B$36,$A$2:$A$36,1,1) -> 2.5776548 | D46: =C46-_xlfn.FORECAST.ETS.CONFINT(A46,$B$2:$B$36,$A$2:$A$36,0.95,1,1) -> 1.0651961 | E46: =C46+_xlfn.FORECAST.ETS.CONFINT(A46,$B$2:$B$36,$A$2:$A$36,0.95,1,1) -> 4.0901135
A47: 45337 | C47: =_xlfn.FORECAST.ETS(A47,$B$2:$B$36,$A$2:$A$36,1,1) -> 2.5876719 | D47: =C47-_xlfn.FORECAST.ETS.CONFINT(A47,$B$2:$B$36,$A$2:$A$36,0.95,1,1) -> 1.0631461 | E47: =C47+_xlfn.FORECAST.ETS.CONFINT(A47,$B$2:$B$36,$A$2:$A$36,0.95,1,1) -> 4.1121978
A48: 45338 | C48: =_xlfn.FORECAST.ETS(A48,$B$2:$B$36,$A$2:$A$36,1,1) -> 2.597689 | D48: =C48-_xlfn.FORECAST.ETS.CONFINT(A48,$B$2:$B$36,$A$2:$A$36,0.95,1,1) -> 1.0610148 | E48: =C48+_xlfn.FORECAST.ETS.CONFINT(A48,$B$2:$B$36,$A$2:$A$36,0.95,1,1) -> 4.1343633
... A62: 45352 | C62: =_xlfn.FORECAST.ETS(A62,$B$2:$B$36,$A$2:$A$36,1,1) -> 2.7379285 | D62: =C62-_xlfn.FORECAST.ETS.CONFINT(A62,$B$2:$B$36,$A$2:$A$36,0.95,1,1) -> 1.0229867 | E62: =C62+_xlfn.FORECAST.ETS.CONFINT(A62,$B$2:$B$36,$A$2:$A$36,0.95,1,1) -> 4.4528702

Sheet Box Plot
A1: Retail_Price(USD) | B1: Order_Quantity | C1: Total_(USD)
A2: 49.99 | B2: 2 | C2: 109.978
A3: 29.99 | B3: 1 | C3: 32.989
A4: 99.99 | B4: 3 | C4: 329.967
A5: 19.99 | B5: 4 | C5: 87.956
A6: 149.99 | B6: 1 | C6: 164.989
A7: 79.99 | B7: 2 | C7: 175.978
A8: 39.99 | B8: 3 | C8: 131.967
A9: 69.99 | B9: 2 | C9: 153.978
A10: 89.99 | B10: 1 | C10: 98.989
A11: 199.99 | B11: 1 | C11: 219.989
A12: 29.99 | B12: 5 | C12: 164.945
A13: 79.99 | B13: 2 | C13: 175.978
... A71: 149.99 | B71: 1 | C71: 164.989
